2022-05-05 12:18:45,186:django.utils.autoreload:C:\Dev\dj_domconnect\domconnect\lib_seo.py changed, reloading.
2022-05-05 12:18:51,744:domconnect.views:list index out of range
2022-05-05 12:18:58,677:domconnect.views:list index out of range
2022-05-05 12:19:58,652:domconnect.views:list index out of range
2022-05-05 12:20:45,320:django.utils.autoreload:C:\Dev\dj_domconnect\domconnect\lib_seo.py changed, reloading.
2022-05-05 12:22:20,182:django.utils.autoreload:C:\Dev\dj_domconnect\domconnect\lib_seo.py changed, reloading.
2022-05-05 12:22:33,911:domconnect.lib_seo:Œ¯Ë·Í‡ make_csv_text: try: list index out of range
2022-05-05 12:29:27,242:django.utils.autoreload:C:\Dev\dj_domconnect\domconnect\lib_seo.py changed, reloading.
2022-05-05 12:29:36,365:domconnect.lib_seo:Œ¯Ë·Í‡ make_csv_text: try: list index out of range
2022-05-05 14:49:49,743:django.utils.autoreload:C:\Dev\dj_domconnect\domconnect\lib_seo.py changed, reloading.
2022-05-05 14:49:54,986:domconnect.lib_seo:Œ¯Ë·Í‡ make_csv_text: try: list index out of range
2022-05-05 14:52:45,120:django.utils.autoreload:C:\Dev\dj_domconnect\domconnect\lib_seo.py changed, reloading.
2022-05-05 14:53:19,107:django.utils.autoreload:C:\Dev\dj_domconnect\domconnect\lib_seo.py changed, reloading.
2022-05-05 15:19:05,928:django.utils.autoreload:C:\Dev\dj_domconnect\domconnect\lib_seo.py changed, reloading.
2022-05-06 09:23:36,668:django.request:Not Found: /favicon.ico
2022-05-06 09:41:41,036:django.utils.autoreload:C:\Dev\dj_domconnect\domconnect\lib_seo.py changed, reloading.
2022-05-06 09:41:50,935:domconnect.lib_seo:Œ¯Ë·Í‡ make_csv_text: try: unsupported operand type(s) for -: 'list' and 'int'
2022-05-06 09:47:11,398:django.utils.autoreload:C:\Dev\dj_domconnect\domconnect\lib_seo.py changed, reloading.
2022-05-18 15:46:20,615:django.request:Not Found: /favicon.ico
2022-05-27 11:20:38,984:django.request:Not Found: /auth/jwt/create/
2022-05-27 11:26:55,303:django.utils.autoreload:C:\Dev\dj_domconnect\api\urls.py changed, reloading.
2022-05-27 11:27:26,172:django.request:Unauthorized: /auth/jwt/create/
2022-05-27 11:28:57,289:django.utils.autoreload:C:\Dev\dj_domconnect\core\urls.py changed, reloading.
2022-05-27 11:30:42,719:django.request:Not Found: /api/get_pv_result
2022-05-27 11:31:23,018:django.request:Not Found: /api/get_pv_result/
2022-05-27 11:31:42,894:django.request:Internal Server Error: /api/get_pv_result/0/hhh
Traceback (most recent call last):
  File "c:\Dev\dj_domconnect\venv\lib\site-packages\django\core\handlers\exception.py", line 34, in inner
    response = get_response(request)
  File "c:\Dev\dj_domconnect\venv\lib\site-packages\django\core\handlers\base.py", line 145, in _get_response
    response = self.process_exception_by_middleware(e, request)
  File "c:\Dev\dj_domconnect\venv\lib\site-packages\django\core\handlers\base.py", line 143, in _get_response
    response = response.render()
  File "c:\Dev\dj_domconnect\venv\lib\site-packages\django\template\response.py", line 105, in render
    self.content = self.rendered_content
  File "c:\Dev\dj_domconnect\venv\lib\site-packages\rest_framework\response.py", line 55, in rendered_content
    assert renderer, ".accepted_renderer not set on Response"
AssertionError: .accepted_renderer not set on Response
2022-05-27 11:37:02,882:django.request:Not Found: /get_bots_info.10,02,22
2022-05-27 11:37:22,328:django.request:Not Found: /get_bots_info/10.02.22
2022-05-27 11:38:19,477:django.utils.autoreload:C:\Dev\dj_domconnect\api\views.py changed, reloading.
2022-05-27 11:56:37,486:django.utils.autoreload:C:\Dev\dj_domconnect\api\views.py changed, reloading.
2022-05-27 12:00:33,592:django.request:Not Found: /api/set_pv_result/
2022-05-27 12:02:23,985:django.request:Not Found: /api/set_pv_result/
2022-05-27 12:03:10,744:django.utils.autoreload:C:\Dev\dj_domconnect\api\urls.py changed, reloading.
2022-05-27 12:04:15,388:django.utils.autoreload:C:\Dev\dj_domconnect\api\urls.py changed, reloading.
2022-05-27 12:04:29,444:django.request:Not Found: /api/set_pv_result/
2022-05-27 12:04:41,481:django.utils.autoreload:C:\Dev\dj_domconnect\api\urls.py changed, reloading.
2022-05-27 12:04:47,334:django.security.csrf:Forbidden (CSRF cookie not set.): /api/set_pv_result/
2022-05-27 12:10:40,977:django.utils.autoreload:C:\Dev\dj_domconnect\api\views.py changed, reloading.
2022-05-27 12:11:11,255:django.request:Internal Server Error: /api/set_pv_result/
Traceback (most recent call last):
  File "c:\Dev\dj_domconnect\venv\lib\site-packages\django\core\handlers\exception.py", line 34, in inner
    response = get_response(request)
  File "c:\Dev\dj_domconnect\venv\lib\site-packages\django\core\handlers\base.py", line 115, in _get_response
    response = self.process_exception_by_middleware(e, request)
  File "c:\Dev\dj_domconnect\venv\lib\site-packages\django\core\handlers\base.py", line 113, in _get_response
    response = wrapped_callback(request, *callback_args, **callback_kwargs)
  File "c:\Dev\dj_domconnect\venv\lib\site-packages\django\views\decorators\csrf.py", line 54, in wrapped_view
    return view_func(*args, **kwargs)
TypeError: __init__() takes 1 positional argument but 2 were given
2022-05-27 12:19:50,958:django.utils.autoreload:C:\Dev\dj_domconnect\api\views.py changed, reloading.
2022-05-27 12:20:17,215:django.security.csrf:Forbidden (CSRF cookie not set.): /api/set_pv_result/
2022-05-27 12:21:59,993:django.utils.autoreload:C:\Dev\dj_domconnect\api\views.py changed, reloading.
2022-05-27 12:22:05,412:django.request:Internal Server Error: /api/set_pv_result/
Traceback (most recent call last):
  File "c:\Dev\dj_domconnect\venv\lib\site-packages\django\core\handlers\exception.py", line 34, in inner
    response = get_response(request)
  File "c:\Dev\dj_domconnect\venv\lib\site-packages\django\core\handlers\base.py", line 115, in _get_response
    response = self.process_exception_by_middleware(e, request)
  File "c:\Dev\dj_domconnect\venv\lib\site-packages\django\core\handlers\base.py", line 113, in _get_response
    response = wrapped_callback(request, *callback_args, **callback_kwargs)
  File "c:\Dev\dj_domconnect\venv\lib\site-packages\django\views\decorators\csrf.py", line 54, in wrapped_view
    return view_func(*args, **kwargs)
TypeError: __init__() takes 1 positional argument but 2 were given
2022-05-27 12:26:22,564:django.utils.autoreload:C:\Dev\dj_domconnect\api\views.py changed, reloading.
2022-05-27 12:26:30,257:django.request:Internal Server Error: /api/set_pv_result/
Traceback (most recent call last):
  File "c:\Dev\dj_domconnect\venv\lib\site-packages\django\core\handlers\exception.py", line 34, in inner
    response = get_response(request)
  File "c:\Dev\dj_domconnect\venv\lib\site-packages\django\core\handlers\base.py", line 115, in _get_response
    response = self.process_exception_by_middleware(e, request)
  File "c:\Dev\dj_domconnect\venv\lib\site-packages\django\core\handlers\base.py", line 113, in _get_response
    response = wrapped_callback(request, *callback_args, **callback_kwargs)
  File "c:\Dev\dj_domconnect\venv\lib\site-packages\django\views\decorators\csrf.py", line 54, in wrapped_view
    return view_func(*args, **kwargs)
TypeError: __init__() takes 1 positional argument but 2 were given
2022-05-27 12:27:04,892:django.utils.autoreload:C:\Dev\dj_domconnect\api\views.py changed, reloading.
2022-05-27 12:27:19,921:django.request:Internal Server Error: /api/set_pv_result/
Traceback (most recent call last):
  File "c:\Dev\dj_domconnect\venv\lib\site-packages\django\core\handlers\exception.py", line 34, in inner
    response = get_response(request)
  File "c:\Dev\dj_domconnect\venv\lib\site-packages\django\core\handlers\base.py", line 115, in _get_response
    response = self.process_exception_by_middleware(e, request)
  File "c:\Dev\dj_domconnect\venv\lib\site-packages\django\core\handlers\base.py", line 113, in _get_response
    response = wrapped_callback(request, *callback_args, **callback_kwargs)
  File "c:\Dev\dj_domconnect\venv\lib\site-packages\django\views\decorators\csrf.py", line 54, in wrapped_view
    return view_func(*args, **kwargs)
TypeError: __init__() takes 1 positional argument but 2 were given
2022-05-27 12:27:28,449:django.request:Internal Server Error: /api/set_pv_result/
Traceback (most recent call last):
  File "c:\Dev\dj_domconnect\venv\lib\site-packages\django\core\handlers\exception.py", line 34, in inner
    response = get_response(request)
  File "c:\Dev\dj_domconnect\venv\lib\site-packages\django\core\handlers\base.py", line 115, in _get_response
    response = self.process_exception_by_middleware(e, request)
  File "c:\Dev\dj_domconnect\venv\lib\site-packages\django\core\handlers\base.py", line 113, in _get_response
    response = wrapped_callback(request, *callback_args, **callback_kwargs)
  File "c:\Dev\dj_domconnect\venv\lib\site-packages\django\views\decorators\csrf.py", line 54, in wrapped_view
    return view_func(*args, **kwargs)
TypeError: __init__() takes 1 positional argument but 2 were given
2022-05-27 12:27:33,041:django.request:Internal Server Error: /api/set_pv_result/
Traceback (most recent call last):
  File "c:\Dev\dj_domconnect\venv\lib\site-packages\django\core\handlers\exception.py", line 34, in inner
    response = get_response(request)
  File "c:\Dev\dj_domconnect\venv\lib\site-packages\django\core\handlers\base.py", line 115, in _get_response
    response = self.process_exception_by_middleware(e, request)
  File "c:\Dev\dj_domconnect\venv\lib\site-packages\django\core\handlers\base.py", line 113, in _get_response
    response = wrapped_callback(request, *callback_args, **callback_kwargs)
  File "c:\Dev\dj_domconnect\venv\lib\site-packages\django\views\decorators\csrf.py", line 54, in wrapped_view
    return view_func(*args, **kwargs)
TypeError: __init__() takes 1 positional argument but 2 were given
2022-05-27 12:28:21,766:django.utils.autoreload:C:\Dev\dj_domconnect\core\settings.py changed, reloading.
2022-05-27 12:28:26,982:django.utils.autoreload:C:\Dev\dj_domconnect\api\views.py changed, reloading.
2022-05-27 12:28:32,720:django.request:Internal Server Error: /api/set_pv_result/
Traceback (most recent call last):
  File "c:\Dev\dj_domconnect\venv\lib\site-packages\django\core\handlers\exception.py", line 34, in inner
    response = get_response(request)
  File "c:\Dev\dj_domconnect\venv\lib\site-packages\django\core\handlers\base.py", line 115, in _get_response
    response = self.process_exception_by_middleware(e, request)
  File "c:\Dev\dj_domconnect\venv\lib\site-packages\django\core\handlers\base.py", line 113, in _get_response
    response = wrapped_callback(request, *callback_args, **callback_kwargs)
TypeError: __init__() takes 1 positional argument but 2 were given
2022-05-27 12:29:18,139:django.utils.autoreload:C:\Dev\dj_domconnect\core\settings.py changed, reloading.
2022-05-27 12:29:23,382:django.security.csrf:Forbidden (CSRF cookie not set.): /api/set_pv_result/
2022-05-27 12:29:34,227:django.utils.autoreload:C:\Dev\dj_domconnect\api\views.py changed, reloading.
2022-05-27 12:29:56,203:django.utils.autoreload:C:\Dev\dj_domconnect\api\views.py changed, reloading.
2022-05-27 12:30:01,356:django.request:Internal Server Error: /api/set_pv_result/
Traceback (most recent call last):
  File "c:\Dev\dj_domconnect\venv\lib\site-packages\django\core\handlers\exception.py", line 34, in inner
    response = get_response(request)
  File "c:\Dev\dj_domconnect\venv\lib\site-packages\django\core\handlers\base.py", line 115, in _get_response
    response = self.process_exception_by_middleware(e, request)
  File "c:\Dev\dj_domconnect\venv\lib\site-packages\django\core\handlers\base.py", line 113, in _get_response
    response = wrapped_callback(request, *callback_args, **callback_kwargs)
  File "c:\Dev\dj_domconnect\venv\lib\site-packages\django\views\decorators\csrf.py", line 54, in wrapped_view
    return view_func(*args, **kwargs)
TypeError: __init__() takes 1 positional argument but 2 were given
2022-05-27 12:30:18,152:django.utils.autoreload:C:\Dev\dj_domconnect\api\views.py changed, reloading.
2022-05-27 12:30:22,574:django.request:Internal Server Error: /api/set_pv_result/
Traceback (most recent call last):
  File "c:\Dev\dj_domconnect\venv\lib\site-packages\django\core\handlers\exception.py", line 34, in inner
    response = get_response(request)
  File "c:\Dev\dj_domconnect\venv\lib\site-packages\django\core\handlers\base.py", line 115, in _get_response
    response = self.process_exception_by_middleware(e, request)
  File "c:\Dev\dj_domconnect\venv\lib\site-packages\django\core\handlers\base.py", line 113, in _get_response
    response = wrapped_callback(request, *callback_args, **callback_kwargs)
  File "c:\Dev\dj_domconnect\venv\lib\site-packages\django\views\decorators\csrf.py", line 54, in wrapped_view
    return view_func(*args, **kwargs)
TypeError: __init__() takes 1 positional argument but 2 were given
2022-05-27 12:33:02,559:django.utils.autoreload:C:\Dev\dj_domconnect\api\serializers.py changed, reloading.
2022-05-27 12:33:18,575:django.utils.autoreload:C:\Dev\dj_domconnect\api\serializers.py changed, reloading.
2022-05-27 12:34:10,152:django.request:Internal Server Error: /api/set_pv_result/
Traceback (most recent call last):
  File "c:\Dev\dj_domconnect\venv\lib\site-packages\django\core\handlers\exception.py", line 34, in inner
    response = get_response(request)
  File "c:\Dev\dj_domconnect\venv\lib\site-packages\django\core\handlers\base.py", line 115, in _get_response
    response = self.process_exception_by_middleware(e, request)
  File "c:\Dev\dj_domconnect\venv\lib\site-packages\django\core\handlers\base.py", line 113, in _get_response
    response = wrapped_callback(request, *callback_args, **callback_kwargs)
  File "c:\Dev\dj_domconnect\venv\lib\site-packages\django\views\decorators\csrf.py", line 54, in wrapped_view
    return view_func(*args, **kwargs)
TypeError: __init__() takes 1 positional argument but 2 were given
2022-05-27 12:34:33,447:django.security.csrf:Forbidden (CSRF cookie not set.): /api/get_pv_result/0/hhh
2022-05-27 12:34:49,319:django.security.csrf:Forbidden (CSRF cookie not set.): /api/get_pv_result/0/hhh
2022-05-27 12:35:04,854:django.security.csrf:Forbidden (CSRF cookie not set.): /api/get_pv_result/0/hhh
2022-05-27 12:35:22,838:django.request:Internal Server Error: /api/set_pv_result/
Traceback (most recent call last):
  File "c:\Dev\dj_domconnect\venv\lib\site-packages\django\core\handlers\exception.py", line 34, in inner
    response = get_response(request)
  File "c:\Dev\dj_domconnect\venv\lib\site-packages\django\core\handlers\base.py", line 115, in _get_response
    response = self.process_exception_by_middleware(e, request)
  File "c:\Dev\dj_domconnect\venv\lib\site-packages\django\core\handlers\base.py", line 113, in _get_response
    response = wrapped_callback(request, *callback_args, **callback_kwargs)
  File "c:\Dev\dj_domconnect\venv\lib\site-packages\django\views\decorators\csrf.py", line 54, in wrapped_view
    return view_func(*args, **kwargs)
TypeError: __init__() takes 1 positional argument but 2 were given
2022-05-27 12:35:35,901:django.request:Internal Server Error: /api/set_pv_result
Traceback (most recent call last):
  File "c:\Dev\dj_domconnect\venv\lib\site-packages\django\core\handlers\exception.py", line 34, in inner
    response = get_response(request)
  File "c:\Dev\dj_domconnect\venv\lib\site-packages\django\utils\deprecation.py", line 93, in __call__
    response = self.process_request(request)
  File "c:\Dev\dj_domconnect\venv\lib\site-packages\django\middleware\common.py", line 54, in process_request
    path = self.get_full_path_with_slash(request)
  File "c:\Dev\dj_domconnect\venv\lib\site-packages\django\middleware\common.py", line 87, in get_full_path_with_slash
    raise RuntimeError(
RuntimeError: You called this URL via POST, but the URL doesn't end in a slash and you have APPEND_SLASH set. Django can't redirect to the slash URL while maintaining POST data. Change your form to point to localhost:8000/api/set_pv_result/ (note the trailing slash), or set APPEND_SLASH=False in your Django settings.
2022-05-27 12:35:50,646:django.utils.autoreload:C:\Dev\dj_domconnect\api\urls.py changed, reloading.
2022-05-27 12:35:57,647:django.request:Internal Server Error: /api/set_pv_result
Traceback (most recent call last):
  File "c:\Dev\dj_domconnect\venv\lib\site-packages\django\core\handlers\exception.py", line 34, in inner
    response = get_response(request)
  File "c:\Dev\dj_domconnect\venv\lib\site-packages\django\core\handlers\base.py", line 115, in _get_response
    response = self.process_exception_by_middleware(e, request)
  File "c:\Dev\dj_domconnect\venv\lib\site-packages\django\core\handlers\base.py", line 113, in _get_response
    response = wrapped_callback(request, *callback_args, **callback_kwargs)
  File "c:\Dev\dj_domconnect\venv\lib\site-packages\django\views\decorators\csrf.py", line 54, in wrapped_view
    return view_func(*args, **kwargs)
TypeError: __init__() takes 1 positional argument but 2 were given
2022-05-27 12:39:22,689:django.utils.autoreload:C:\Dev\dj_domconnect\api\urls.py changed, reloading.
2022-05-27 12:42:48,751:django.utils.autoreload:C:\Dev\dj_domconnect\api\views.py changed, reloading.
2022-05-27 12:42:54,481:django.request:Internal Server Error: /api/set_pv_result
Traceback (most recent call last):
  File "c:\Dev\dj_domconnect\venv\lib\site-packages\django\core\handlers\exception.py", line 34, in inner
    response = get_response(request)
  File "c:\Dev\dj_domconnect\venv\lib\site-packages\django\core\handlers\base.py", line 115, in _get_response
    response = self.process_exception_by_middleware(e, request)
  File "c:\Dev\dj_domconnect\venv\lib\site-packages\django\core\handlers\base.py", line 113, in _get_response
    response = wrapped_callback(request, *callback_args, **callback_kwargs)
  File "c:\Dev\dj_domconnect\venv\lib\site-packages\django\views\decorators\csrf.py", line 54, in wrapped_view
    return view_func(*args, **kwargs)
TypeError: __init__() takes 1 positional argument but 2 were given
2022-05-27 12:44:23,497:django.utils.autoreload:C:\Dev\dj_domconnect\api\views.py changed, reloading.
2022-05-27 12:44:30,430:django.request:Internal Server Error: /api/set_pv_result
Traceback (most recent call last):
  File "c:\Dev\dj_domconnect\venv\lib\site-packages\django\core\handlers\exception.py", line 34, in inner
    response = get_response(request)
  File "c:\Dev\dj_domconnect\venv\lib\site-packages\django\core\handlers\base.py", line 115, in _get_response
    response = self.process_exception_by_middleware(e, request)
  File "c:\Dev\dj_domconnect\venv\lib\site-packages\django\core\handlers\base.py", line 113, in _get_response
    response = wrapped_callback(request, *callback_args, **callback_kwargs)
  File "c:\Dev\dj_domconnect\venv\lib\site-packages\django\views\decorators\csrf.py", line 54, in wrapped_view
    return view_func(*args, **kwargs)
TypeError: __init__() takes 1 positional argument but 2 were given
2022-05-27 12:47:35,349:django.utils.autoreload:C:\Dev\dj_domconnect\api\urls.py changed, reloading.
2022-05-27 13:10:32,002:django.request:Internal Server Error: /api/set_pv_result
Traceback (most recent call last):
  File "c:\Dev\dj_domconnect\venv\lib\site-packages\django\core\handlers\exception.py", line 34, in inner
    response = get_response(request)
  File "c:\Dev\dj_domconnect\venv\lib\site-packages\django\utils\deprecation.py", line 93, in __call__
    response = self.process_request(request)
  File "c:\Dev\dj_domconnect\venv\lib\site-packages\django\middleware\common.py", line 54, in process_request
    path = self.get_full_path_with_slash(request)
  File "c:\Dev\dj_domconnect\venv\lib\site-packages\django\middleware\common.py", line 87, in get_full_path_with_slash
    raise RuntimeError(
RuntimeError: You called this URL via POST, but the URL doesn't end in a slash and you have APPEND_SLASH set. Django can't redirect to the slash URL while maintaining POST data. Change your form to point to localhost:8000/api/set_pv_result/ (note the trailing slash), or set APPEND_SLASH=False in your Django settings.
2022-05-27 13:11:16,982:django.request:Bad Request: /api/set_pv_result/
2022-05-27 13:11:57,797:django.utils.autoreload:C:\Dev\dj_domconnect\api\views.py changed, reloading.
2022-05-27 13:12:17,068:django.utils.autoreload:C:\Dev\dj_domconnect\api\serializers.py changed, reloading.
2022-05-27 13:12:22,677:django.request:Bad Request: /api/set_pv_result/
2022-05-27 13:12:32,962:django.request:Bad Request: /api/set_pv_result/
2022-05-27 13:14:41,544:django.utils.autoreload:C:\Dev\dj_domconnect\api\urls.py changed, reloading.
2022-05-27 13:14:48,032:django.request:Bad Request: /api/set_pv_result/
2022-05-27 13:15:36,443:django.utils.autoreload:C:\Dev\dj_domconnect\api\urls.py changed, reloading.
2022-05-27 13:16:22,247:django.request:Not Found: /api/set_pv_result/
2022-05-27 13:17:38,057:django.utils.autoreload:C:\Dev\dj_domconnect\api\urls.py changed, reloading.
2022-05-27 13:52:08,925:django.request:Bad Request: /api/set_pv_result/
2022-05-27 13:57:33,352:django.utils.autoreload:C:\Dev\dj_domconnect\api\serializers.py changed, reloading.
2022-05-27 13:57:43,946:django.request:Bad Request: /api/set_pv_result/
2022-05-27 14:06:10,256:django.utils.autoreload:C:\Dev\dj_domconnect\api\views.py changed, reloading.
2022-05-27 14:06:25,343:django.request:Bad Request: /api/set_pv_result/
2022-05-27 14:08:20,653:django.utils.autoreload:C:\Dev\dj_domconnect\api\views.py changed, reloading.
2022-05-27 14:08:26,117:django.request:Bad Request: /api/set_pv_result/
2022-05-27 14:13:05,717:django.utils.autoreload:C:\Dev\dj_domconnect\api\views.py changed, reloading.
2022-05-27 14:13:15,234:django.request:Internal Server Error: /api/set_pv_result/
Traceback (most recent call last):
  File "c:\Dev\dj_domconnect\venv\lib\site-packages\django\core\handlers\exception.py", line 34, in inner
    response = get_response(request)
  File "c:\Dev\dj_domconnect\venv\lib\site-packages\django\core\handlers\base.py", line 115, in _get_response
    response = self.process_exception_by_middleware(e, request)
  File "c:\Dev\dj_domconnect\venv\lib\site-packages\django\core\handlers\base.py", line 113, in _get_response
    response = wrapped_callback(request, *callback_args, **callback_kwargs)
  File "c:\Dev\dj_domconnect\venv\lib\site-packages\django\views\decorators\csrf.py", line 54, in wrapped_view
    return view_func(*args, **kwargs)
  File "c:\Dev\dj_domconnect\venv\lib\site-packages\rest_framework\viewsets.py", line 114, in view
    return self.dispatch(request, *args, **kwargs)
  File "c:\Dev\dj_domconnect\venv\lib\site-packages\rest_framework\views.py", line 505, in dispatch
    response = self.handle_exception(exc)
  File "c:\Dev\dj_domconnect\venv\lib\site-packages\rest_framework\views.py", line 465, in handle_exception
    self.raise_uncaught_exception(exc)
  File "c:\Dev\dj_domconnect\venv\lib\site-packages\rest_framework\views.py", line 476, in raise_uncaught_exception
    raise exc
  File "c:\Dev\dj_domconnect\venv\lib\site-packages\rest_framework\views.py", line 502, in dispatch
    response = handler(request, *args, **kwargs)
  File "c:\Dev\dj_domconnect\venv\lib\site-packages\rest_framework\mixins.py", line 17, in create
    serializer = self.get_serializer(data=request.data)
  File "c:\Dev\dj_domconnect\venv\lib\site-packages\rest_framework\generics.py", line 110, in get_serializer
    return serializer_class(*args, **kwargs)
TypeError: 'ListSerializer' object is not callable
2022-05-27 14:14:42,417:django.utils.autoreload:C:\Dev\dj_domconnect\api\serializers.py changed, reloading.
2022-05-27 14:16:24,940:django.utils.autoreload:C:\Dev\dj_domconnect\api\views.py changed, reloading.
2022-05-27 14:16:30,387:django.request:Internal Server Error: /api/set_pv_result/
Traceback (most recent call last):
  File "c:\Dev\dj_domconnect\venv\lib\site-packages\django\core\handlers\exception.py", line 34, in inner
    response = get_response(request)
  File "c:\Dev\dj_domconnect\venv\lib\site-packages\django\core\handlers\base.py", line 115, in _get_response
    response = self.process_exception_by_middleware(e, request)
  File "c:\Dev\dj_domconnect\venv\lib\site-packages\django\core\handlers\base.py", line 113, in _get_response
    response = wrapped_callback(request, *callback_args, **callback_kwargs)
  File "c:\Dev\dj_domconnect\venv\lib\site-packages\django\views\decorators\csrf.py", line 54, in wrapped_view
    return view_func(*args, **kwargs)
  File "c:\Dev\dj_domconnect\venv\lib\site-packages\rest_framework\viewsets.py", line 114, in view
    return self.dispatch(request, *args, **kwargs)
  File "c:\Dev\dj_domconnect\venv\lib\site-packages\rest_framework\views.py", line 505, in dispatch
    response = self.handle_exception(exc)
  File "c:\Dev\dj_domconnect\venv\lib\site-packages\rest_framework\views.py", line 465, in handle_exception
    self.raise_uncaught_exception(exc)
  File "c:\Dev\dj_domconnect\venv\lib\site-packages\rest_framework\views.py", line 476, in raise_uncaught_exception
    raise exc
  File "c:\Dev\dj_domconnect\venv\lib\site-packages\rest_framework\views.py", line 502, in dispatch
    response = handler(request, *args, **kwargs)
  File "c:\Dev\dj_domconnect\venv\lib\site-packages\rest_framework\mixins.py", line 17, in create
    serializer = self.get_serializer(data=request.data)
  File "c:\Dev\dj_domconnect\venv\lib\site-packages\rest_framework\generics.py", line 110, in get_serializer
    return serializer_class(*args, **kwargs)
TypeError: 'ListSerializer' object is not callable
2022-05-27 14:17:11,519:django.request:Bad Request: /api/set_pv_result/
2022-05-27 14:17:31,273:django.request:Internal Server Error: /api/set_pv_result/
Traceback (most recent call last):
  File "c:\Dev\dj_domconnect\venv\lib\site-packages\django\core\handlers\exception.py", line 34, in inner
    response = get_response(request)
  File "c:\Dev\dj_domconnect\venv\lib\site-packages\django\core\handlers\base.py", line 115, in _get_response
    response = self.process_exception_by_middleware(e, request)
  File "c:\Dev\dj_domconnect\venv\lib\site-packages\django\core\handlers\base.py", line 113, in _get_response
    response = wrapped_callback(request, *callback_args, **callback_kwargs)
  File "c:\Dev\dj_domconnect\venv\lib\site-packages\django\views\decorators\csrf.py", line 54, in wrapped_view
    return view_func(*args, **kwargs)
  File "c:\Dev\dj_domconnect\venv\lib\site-packages\rest_framework\viewsets.py", line 114, in view
    return self.dispatch(request, *args, **kwargs)
  File "c:\Dev\dj_domconnect\venv\lib\site-packages\rest_framework\views.py", line 505, in dispatch
    response = self.handle_exception(exc)
  File "c:\Dev\dj_domconnect\venv\lib\site-packages\rest_framework\views.py", line 465, in handle_exception
    self.raise_uncaught_exception(exc)
  File "c:\Dev\dj_domconnect\venv\lib\site-packages\rest_framework\views.py", line 476, in raise_uncaught_exception
    raise exc
  File "c:\Dev\dj_domconnect\venv\lib\site-packages\rest_framework\views.py", line 502, in dispatch
    response = handler(request, *args, **kwargs)
  File "c:\Dev\dj_domconnect\venv\lib\site-packages\rest_framework\mixins.py", line 17, in create
    serializer = self.get_serializer(data=request.data)
  File "c:\Dev\dj_domconnect\venv\lib\site-packages\rest_framework\generics.py", line 110, in get_serializer
    return serializer_class(*args, **kwargs)
TypeError: 'ListSerializer' object is not callable
2022-05-27 14:18:00,730:django.utils.autoreload:C:\Dev\dj_domconnect\api\views.py changed, reloading.
2022-05-27 14:18:07,468:django.request:Internal Server Error: /api/set_pv_result/
Traceback (most recent call last):
  File "c:\Dev\dj_domconnect\venv\lib\site-packages\django\core\handlers\exception.py", line 34, in inner
    response = get_response(request)
  File "c:\Dev\dj_domconnect\venv\lib\site-packages\django\core\handlers\base.py", line 115, in _get_response
    response = self.process_exception_by_middleware(e, request)
  File "c:\Dev\dj_domconnect\venv\lib\site-packages\django\core\handlers\base.py", line 113, in _get_response
    response = wrapped_callback(request, *callback_args, **callback_kwargs)
  File "c:\Dev\dj_domconnect\venv\lib\site-packages\django\views\decorators\csrf.py", line 54, in wrapped_view
    return view_func(*args, **kwargs)
  File "c:\Dev\dj_domconnect\venv\lib\site-packages\rest_framework\viewsets.py", line 114, in view
    return self.dispatch(request, *args, **kwargs)
  File "c:\Dev\dj_domconnect\venv\lib\site-packages\rest_framework\views.py", line 505, in dispatch
    response = self.handle_exception(exc)
  File "c:\Dev\dj_domconnect\venv\lib\site-packages\rest_framework\views.py", line 465, in handle_exception
    self.raise_uncaught_exception(exc)
  File "c:\Dev\dj_domconnect\venv\lib\site-packages\rest_framework\views.py", line 476, in raise_uncaught_exception
    raise exc
  File "c:\Dev\dj_domconnect\venv\lib\site-packages\rest_framework\views.py", line 502, in dispatch
    response = handler(request, *args, **kwargs)
  File "c:\Dev\dj_domconnect\venv\lib\site-packages\rest_framework\mixins.py", line 17, in create
    serializer = self.get_serializer(data=request.data)
  File "c:\Dev\dj_domconnect\venv\lib\site-packages\rest_framework\generics.py", line 110, in get_serializer
    return serializer_class(*args, **kwargs)
TypeError: 'ListSerializer' object is not callable
2022-05-27 14:18:12,609:django.request:Internal Server Error: /api/set_pv_result/
Traceback (most recent call last):
  File "c:\Dev\dj_domconnect\venv\lib\site-packages\django\core\handlers\exception.py", line 34, in inner
    response = get_response(request)
  File "c:\Dev\dj_domconnect\venv\lib\site-packages\django\core\handlers\base.py", line 115, in _get_response
    response = self.process_exception_by_middleware(e, request)
  File "c:\Dev\dj_domconnect\venv\lib\site-packages\django\core\handlers\base.py", line 113, in _get_response
    response = wrapped_callback(request, *callback_args, **callback_kwargs)
  File "c:\Dev\dj_domconnect\venv\lib\site-packages\django\views\decorators\csrf.py", line 54, in wrapped_view
    return view_func(*args, **kwargs)
  File "c:\Dev\dj_domconnect\venv\lib\site-packages\rest_framework\viewsets.py", line 114, in view
    return self.dispatch(request, *args, **kwargs)
  File "c:\Dev\dj_domconnect\venv\lib\site-packages\rest_framework\views.py", line 505, in dispatch
    response = self.handle_exception(exc)
  File "c:\Dev\dj_domconnect\venv\lib\site-packages\rest_framework\views.py", line 465, in handle_exception
    self.raise_uncaught_exception(exc)
  File "c:\Dev\dj_domconnect\venv\lib\site-packages\rest_framework\views.py", line 476, in raise_uncaught_exception
    raise exc
  File "c:\Dev\dj_domconnect\venv\lib\site-packages\rest_framework\views.py", line 502, in dispatch
    response = handler(request, *args, **kwargs)
  File "c:\Dev\dj_domconnect\venv\lib\site-packages\rest_framework\mixins.py", line 17, in create
    serializer = self.get_serializer(data=request.data)
  File "c:\Dev\dj_domconnect\venv\lib\site-packages\rest_framework\generics.py", line 110, in get_serializer
    return serializer_class(*args, **kwargs)
TypeError: 'ListSerializer' object is not callable
2022-05-27 14:18:28,654:django.utils.autoreload:C:\Dev\dj_domconnect\api\views.py changed, reloading.
2022-05-27 14:18:37,237:django.request:Bad Request: /api/set_pv_result/
2022-05-27 14:29:07,217:django.utils.autoreload:C:\Dev\dj_domconnect\api\views.py changed, reloading.
2022-05-27 14:29:14,273:django.request:Bad Request: /api/set_pv_result/
2022-05-27 14:29:52,965:django.utils.autoreload:C:\Dev\dj_domconnect\api\views.py changed, reloading.
2022-05-27 14:30:02,561:django.request:Internal Server Error: /api/set_pv_result/
Traceback (most recent call last):
  File "c:\Dev\dj_domconnect\venv\lib\site-packages\django\core\handlers\exception.py", line 34, in inner
    response = get_response(request)
  File "c:\Dev\dj_domconnect\venv\lib\site-packages\django\core\handlers\base.py", line 115, in _get_response
    response = self.process_exception_by_middleware(e, request)
  File "c:\Dev\dj_domconnect\venv\lib\site-packages\django\core\handlers\base.py", line 113, in _get_response
    response = wrapped_callback(request, *callback_args, **callback_kwargs)
  File "c:\Dev\dj_domconnect\venv\lib\site-packages\django\views\decorators\csrf.py", line 54, in wrapped_view
    return view_func(*args, **kwargs)
  File "c:\Dev\dj_domconnect\venv\lib\site-packages\rest_framework\viewsets.py", line 114, in view
    return self.dispatch(request, *args, **kwargs)
  File "c:\Dev\dj_domconnect\venv\lib\site-packages\rest_framework\views.py", line 505, in dispatch
    response = self.handle_exception(exc)
  File "c:\Dev\dj_domconnect\venv\lib\site-packages\rest_framework\views.py", line 465, in handle_exception
    self.raise_uncaught_exception(exc)
  File "c:\Dev\dj_domconnect\venv\lib\site-packages\rest_framework\views.py", line 476, in raise_uncaught_exception
    raise exc
  File "c:\Dev\dj_domconnect\venv\lib\site-packages\rest_framework\views.py", line 502, in dispatch
    response = handler(request, *args, **kwargs)
  File "c:\Dev\dj_domconnect\venv\lib\site-packages\rest_framework\mixins.py", line 17, in create
    serializer = self.get_serializer(data=request.data)
  File "c:\Dev\dj_domconnect\venv\lib\site-packages\rest_framework\generics.py", line 110, in get_serializer
    return serializer_class(*args, **kwargs)
TypeError: 'ListSerializer' object is not callable
2022-05-27 14:32:31,833:django.utils.autoreload:C:\Dev\dj_domconnect\api\views.py changed, reloading.
2022-05-27 14:32:35,872:django.request:Internal Server Error: /api/set_pv_result/
Traceback (most recent call last):
  File "c:\Dev\dj_domconnect\venv\lib\site-packages\django\core\handlers\exception.py", line 34, in inner
    response = get_response(request)
  File "c:\Dev\dj_domconnect\venv\lib\site-packages\django\core\handlers\base.py", line 115, in _get_response
    response = self.process_exception_by_middleware(e, request)
  File "c:\Dev\dj_domconnect\venv\lib\site-packages\django\core\handlers\base.py", line 113, in _get_response
    response = wrapped_callback(request, *callback_args, **callback_kwargs)
  File "c:\Dev\dj_domconnect\venv\lib\site-packages\django\views\decorators\csrf.py", line 54, in wrapped_view
    return view_func(*args, **kwargs)
  File "c:\Dev\dj_domconnect\venv\lib\site-packages\rest_framework\viewsets.py", line 114, in view
    return self.dispatch(request, *args, **kwargs)
  File "c:\Dev\dj_domconnect\venv\lib\site-packages\rest_framework\views.py", line 505, in dispatch
    response = self.handle_exception(exc)
  File "c:\Dev\dj_domconnect\venv\lib\site-packages\rest_framework\views.py", line 465, in handle_exception
    self.raise_uncaught_exception(exc)
  File "c:\Dev\dj_domconnect\venv\lib\site-packages\rest_framework\views.py", line 476, in raise_uncaught_exception
    raise exc
  File "c:\Dev\dj_domconnect\venv\lib\site-packages\rest_framework\views.py", line 502, in dispatch
    response = handler(request, *args, **kwargs)
  File "c:\Dev\dj_domconnect\venv\lib\site-packages\rest_framework\mixins.py", line 17, in create
    serializer = self.get_serializer(data=request.data)
  File "c:\Dev\dj_domconnect\venv\lib\site-packages\rest_framework\generics.py", line 108, in get_serializer
    serializer_class = self.get_serializer_class()
  File "c:\Dev\dj_domconnect\venv\lib\site-packages\rest_framework\generics.py", line 122, in get_serializer_class
    assert self.serializer_class is not None, (
AssertionError: 'SetPvResultViewSet' should either include a `serializer_class` attribute, or override the `get_serializer_class()` method.
2022-05-27 14:41:25,573:django.utils.autoreload:C:\Dev\dj_domconnect\api\views.py changed, reloading.
2022-05-27 14:41:32,413:django.request:Internal Server Error: /api/set_pv_result/
Traceback (most recent call last):
  File "c:\Dev\dj_domconnect\venv\lib\site-packages\django\core\handlers\exception.py", line 34, in inner
    response = get_response(request)
  File "c:\Dev\dj_domconnect\venv\lib\site-packages\django\core\handlers\base.py", line 115, in _get_response
    response = self.process_exception_by_middleware(e, request)
  File "c:\Dev\dj_domconnect\venv\lib\site-packages\django\core\handlers\base.py", line 113, in _get_response
    response = wrapped_callback(request, *callback_args, **callback_kwargs)
  File "c:\Dev\dj_domconnect\venv\lib\site-packages\django\views\decorators\csrf.py", line 54, in wrapped_view
    return view_func(*args, **kwargs)
  File "c:\Dev\dj_domconnect\venv\lib\site-packages\rest_framework\viewsets.py", line 114, in view
    return self.dispatch(request, *args, **kwargs)
  File "c:\Dev\dj_domconnect\venv\lib\site-packages\rest_framework\views.py", line 505, in dispatch
    response = self.handle_exception(exc)
  File "c:\Dev\dj_domconnect\venv\lib\site-packages\rest_framework\views.py", line 465, in handle_exception
    self.raise_uncaught_exception(exc)
  File "c:\Dev\dj_domconnect\venv\lib\site-packages\rest_framework\views.py", line 476, in raise_uncaught_exception
    raise exc
  File "c:\Dev\dj_domconnect\venv\lib\site-packages\rest_framework\views.py", line 502, in dispatch
    response = handler(request, *args, **kwargs)
  File "C:\Dev\dj_domconnect\api\views.py", line 254, in create
    self.perform_create(serializer)
  File "c:\Dev\dj_domconnect\venv\lib\site-packages\rest_framework\mixins.py", line 24, in perform_create
    serializer.save()
  File "c:\Dev\dj_domconnect\venv\lib\site-packages\rest_framework\serializers.py", line 723, in save
    self.instance = self.create(validated_data)
  File "C:\Dev\dj_domconnect\api\serializers.py", line 12, in create
    return PVResult.objects.bulk_create(validated_data, ignore_conflicts=True)
  File "c:\Dev\dj_domconnect\venv\lib\site-packages\django\db\models\manager.py", line 82, in manager_method
    return getattr(self.get_queryset(), name)(*args, **kwargs)
  File "c:\Dev\dj_domconnect\venv\lib\site-packages\django\db\models\query.py", line 476, in bulk_create
    self._populate_pk_values(objs)
  File "c:\Dev\dj_domconnect\venv\lib\site-packages\django\db\models\query.py", line 438, in _populate_pk_values
    if obj.pk is None:
AttributeError: 'dict' object has no attribute 'pk'
2022-05-27 14:43:57,771:django.utils.autoreload:C:\Dev\dj_domconnect\api\serializers.py changed, reloading.
2022-05-27 14:47:38,522:django.utils.autoreload:C:\Dev\dj_domconnect\api\serializers.py changed, reloading.
2022-05-27 14:48:47,821:django.utils.autoreload:C:\Dev\dj_domconnect\api\views.py changed, reloading.
2022-05-27 14:49:40,474:django.request:Not Found: /api/get_liza_phrases/1
2022-05-27 14:50:01,503:django.request:Not Found: /api/get_pz_phrases/1
2022-05-27 16:02:22,167:django.utils.autoreload:C:\Dev\dj_domconnect\api\urls.py changed, reloading.
2022-05-27 16:08:54,448:django.utils.autoreload:C:\Dev\dj_domconnect\api\urls.py changed, reloading.
2022-05-27 16:45:25,098:django.utils.autoreload:C:\Dev\dj_domconnect\api\views.py changed, reloading.
2022-05-27 16:47:53,946:django.utils.autoreload:C:\Dev\dj_domconnect\api\views.py changed, reloading.
2022-05-27 16:48:07,778:django.request:Not Found: /api/get_pv_result/0/
2022-05-27 16:56:39,994:django.utils.autoreload:C:\Dev\dj_domconnect\api\views.py changed, reloading.
2022-05-27 16:57:26,190:django.request:Not Found: /favicon.ico
2022-05-27 17:20:33,295:django.request:Bad Request: /auth/jwt/create/
2022-05-27 17:21:17,393:django.request:Bad Request: /auth/jwt/create/
2022-05-27 17:21:45,643:django.request:Bad Request: /auth/jwt/create/
2022-05-27 17:22:05,736:django.request:Bad Request: /auth/jwt/create/
2022-05-27 17:25:51,683:django.utils.autoreload:C:\Dev\dj_domconnect\api\models.py changed, reloading.
2022-05-27 17:39:11,898:django.request:Internal Server Error: /api/set_pv_result
Traceback (most recent call last):
  File "c:\Dev\dj_domconnect\venv\lib\site-packages\django\core\handlers\exception.py", line 34, in inner
    response = get_response(request)
  File "c:\Dev\dj_domconnect\venv\lib\site-packages\django\utils\deprecation.py", line 93, in __call__
    response = self.process_request(request)
  File "c:\Dev\dj_domconnect\venv\lib\site-packages\django\middleware\common.py", line 54, in process_request
    path = self.get_full_path_with_slash(request)
  File "c:\Dev\dj_domconnect\venv\lib\site-packages\django\middleware\common.py", line 87, in get_full_path_with_slash
    raise RuntimeError(
RuntimeError: You called this URL via POST, but the URL doesn't end in a slash and you have APPEND_SLASH set. Django can't redirect to the slash URL while maintaining POST data. Change your form to point to 127.0.0.1:8000/api/set_pv_result/ (note the trailing slash), or set APPEND_SLASH=False in your Django settings.
2022-05-28 08:45:19,102:django.request:Not Found: /favicon.ico
2022-05-28 08:48:42,053:django.utils.autoreload:C:\Dev\dj_domconnect\api\views.py changed, reloading.
2022-05-28 08:48:51,012:django.request:Internal Server Error: /api/get_pv_result/2/27.05.2022
Traceback (most recent call last):
  File "c:\Dev\dj_domconnect\venv\lib\site-packages\django\core\handlers\exception.py", line 34, in inner
    response = get_response(request)
  File "c:\Dev\dj_domconnect\venv\lib\site-packages\django\core\handlers\base.py", line 115, in _get_response
    response = self.process_exception_by_middleware(e, request)
  File "c:\Dev\dj_domconnect\venv\lib\site-packages\django\core\handlers\base.py", line 113, in _get_response
    response = wrapped_callback(request, *callback_args, **callback_kwargs)
  File "c:\Dev\dj_domconnect\venv\lib\site-packages\django\views\decorators\http.py", line 40, in inner
    return func(request, *args, **kwargs)
  File "C:\Dev\dj_domconnect\api\views.py", line 282, in get_pv_result
    str_obj = f'ID: {obj.get("id_crm")} Ò‰ÂÎÍ‡: {obj.get("num_deal")}'
AttributeError: 'PVResult' object has no attribute 'get'
2022-05-28 08:50:00,818:django.utils.autoreload:C:\Dev\dj_domconnect\api\views.py changed, reloading.
2022-05-28 08:58:42,377:django.utils.autoreload:C:\Dev\dj_domconnect\api\views.py changed, reloading.
2022-05-31 08:21:23,657:django.request:Not Found: /favicon.ico
2022-05-31 08:29:41,050:django.security.RequestDataTooBig:Request body exceeded settings.DATA_UPLOAD_MAX_MEMORY_SIZE.
2022-05-31 08:29:41,190:django.request:Bad Request: /admin/domconnect/dccrmlid/
2022-06-21 09:19:05,289:django.request:Not Found: /favicon.ico
2022-06-21 09:57:53,000:django.utils.autoreload:C:\Dev\dj_domconnect\api\views_txv.py changed, reloading.
