2022-02-24 15:01:40,466:django.utils.autoreload:C:\Dev\dj_domconnect\domconnect\lib_seo.py changed, reloading.
2022-02-24 15:03:35,128:domconnect.views:get_filename None
2022-02-24 15:11:26,316:django.utils.autoreload:C:\Dev\dj_domconnect\domconnect\views.py changed, reloading.
2022-02-24 15:26:51,797:django.utils.autoreload:C:\Dev\dj_domconnect\domconnect\views.py changed, reloading.
2022-02-24 15:35:05,005:django.utils.autoreload:C:\Dev\dj_domconnect\domconnect\views.py changed, reloading.
2022-02-24 15:48:52,464:django.request:Internal Server Error: /domconnect/
Traceback (most recent call last):
  File "c:\Dev\dj_domconnect\venv\lib\site-packages\django\template\base.py", line 469, in parse
    compile_func = self.tags[command]
KeyError: 'endif'

During handling of the above exception, another exception occurred:

Traceback (most recent call last):
  File "c:\Dev\dj_domconnect\venv\lib\site-packages\django\core\handlers\exception.py", line 34, in inner
    response = get_response(request)
  File "c:\Dev\dj_domconnect\venv\lib\site-packages\django\core\handlers\base.py", line 115, in _get_response
    response = self.process_exception_by_middleware(e, request)
  File "c:\Dev\dj_domconnect\venv\lib\site-packages\django\core\handlers\base.py", line 113, in _get_response
    response = wrapped_callback(request, *callback_args, **callback_kwargs)
  File "c:\Dev\dj_domconnect\venv\lib\site-packages\django\contrib\auth\decorators.py", line 21, in _wrapped_view
    return view_func(request, *args, **kwargs)
  File "c:\Dev\dj_domconnect\domconnect\views.py", line 85, in index
    return render(request, 'domconnect/statseo.html', context)
  File "c:\Dev\dj_domconnect\venv\lib\site-packages\django\shortcuts.py", line 19, in render
    content = loader.render_to_string(template_name, context, request, using=using)
  File "c:\Dev\dj_domconnect\venv\lib\site-packages\django\template\loader.py", line 61, in render_to_string
    template = get_template(template_name, using=using)
  File "c:\Dev\dj_domconnect\venv\lib\site-packages\django\template\loader.py", line 15, in get_template
    return engine.get_template(template_name)
  File "c:\Dev\dj_domconnect\venv\lib\site-packages\django\template\backends\django.py", line 34, in get_template
    return Template(self.engine.get_template(template_name), self)
  File "c:\Dev\dj_domconnect\venv\lib\site-packages\django\template\engine.py", line 143, in get_template
    template, origin = self.find_template(template_name)
  File "c:\Dev\dj_domconnect\venv\lib\site-packages\django\template\engine.py", line 125, in find_template
    template = loader.get_template(name, skip=skip)
  File "c:\Dev\dj_domconnect\venv\lib\site-packages\django\template\loaders\base.py", line 29, in get_template
    return Template(
  File "c:\Dev\dj_domconnect\venv\lib\site-packages\django\template\base.py", line 156, in __init__
    self.nodelist = self.compile_nodelist()
  File "c:\Dev\dj_domconnect\venv\lib\site-packages\django\template\base.py", line 194, in compile_nodelist
    return parser.parse()
  File "c:\Dev\dj_domconnect\venv\lib\site-packages\django\template\base.py", line 477, in parse
    raise self.error(token, e)
  File "c:\Dev\dj_domconnect\venv\lib\site-packages\django\template\base.py", line 475, in parse
    compiled_result = compile_func(self, token)
  File "c:\Dev\dj_domconnect\venv\lib\site-packages\django\template\defaulttags.py", line 811, in do_for
    nodelist_loop = parser.parse(('empty', 'endfor',))
  File "c:\Dev\dj_domconnect\venv\lib\site-packages\django\template\base.py", line 471, in parse
    self.invalid_block_tag(token, command, parse_until)
  File "c:\Dev\dj_domconnect\venv\lib\site-packages\django\template\base.py", line 521, in invalid_block_tag
    raise self.error(
django.template.exceptions.TemplateSyntaxError: Invalid block tag on line 958: 'endif', expected 'empty' or 'endfor'. Did you forget to register or load this tag?
2022-02-24 15:52:25,876:django.utils.autoreload:C:\Dev\dj_domconnect\domconnect\views.py changed, reloading.
2022-02-24 15:53:42,158:django.utils.autoreload:C:\Dev\dj_domconnect\domconnect\views.py changed, reloading.
2022-02-24 16:01:57,510:django.utils.autoreload:C:\Dev\dj_domconnect\domconnect\views.py changed, reloading.
2022-02-24 16:02:12,647:django.utils.autoreload:C:\Dev\dj_domconnect\domconnect\views.py changed, reloading.
2022-02-24 16:15:10,673:django.utils.autoreload:C:\Dev\dj_domconnect\domconnect\views.py changed, reloading.
2022-02-24 16:18:04,493:django.utils.autoreload:C:\Dev\dj_domconnect\domconnect\views.py changed, reloading.
2022-02-28 10:37:52,681:domconnect.views:[Errno 2] No such file or directory: 'seo_archive/27-02-2022.json'
2022-02-28 10:37:53,075:django.request:Not Found: /favicon.ico
2022-02-28 10:38:13,530:domconnect.lib_seo:Обновение данных SEO запущено.
2022-02-28 10:38:14,179:domconnect.lib_seo:Загрузка завершена. Обработано сделок: 1. Ошибок: 0
2022-02-28 10:38:22,033:domconnect.views:[Errno 2] No such file or directory: 'seo_archive/27-02-2022.json'
2022-02-28 10:40:09,352:domconnect.lib_seo:Загрузка завершена. Обработано лидов: 2933. Ошибок: 0
2022-02-28 10:43:34,822:domconnect.lib_seo:Расчет и сохранение данных SEO в кэш закончено.
2022-02-28 10:51:54,168:django.utils.autoreload:C:\Dev\dj_domconnect\domconnect\lib_seo.py changed, reloading.
2022-02-28 11:09:18,394:django.utils.autoreload:C:\Dev\dj_domconnect\domconnect\lib_seo.py changed, reloading.
2022-02-28 11:09:49,533:domconnect.lib_seo:Обновение данных SEO запущено.
2022-02-28 11:09:50,215:domconnect.lib_seo:Загрузка завершена. Обработано сделок: 1. Ошибок: 0
2022-02-28 11:09:54,112:domconnect.lib_seo:Загрузка завершена. Обработано лидов: 121. Ошибок: 0
2022-02-28 11:12:03,366:django.utils.autoreload:C:\Dev\dj_domconnect\domconnect\lib_seo.py changed, reloading.
2022-02-28 11:12:16,737:domconnect.views:[Errno 2] No such file or directory: 'seo_archive/27-02-2022.json'
2022-02-28 11:13:13,904:domconnect.views:[Errno 2] No such file or directory: 'seo_archive/27-02-2022.json'
2022-02-28 11:14:03,782:domconnect.lib_seo:Обновение данных SEO запущено.
2022-02-28 11:14:04,323:domconnect.lib_seo:Загрузка завершена. Обработано сделок: 1. Ошибок: 0
2022-02-28 11:14:04,859:domconnect.lib_seo:Загрузка завершена. Обработано лидов: 26. Ошибок: 0
2022-02-28 11:14:06,944:domconnect.views:[Errno 2] No such file or directory: 'seo_archive/27-02-2022.json'
2022-02-28 11:19:52,068:domconnect.lib_seo:Расчет и сохранение данных SEO в кэш закончено.
2022-02-28 11:22:30,083:domconnect.lib_seo:Обновение данных SEO запущено.
2022-02-28 11:22:30,627:domconnect.lib_seo:Загрузка завершена. Обработано сделок: 1. Ошибок: 0
2022-02-28 11:22:31,375:domconnect.lib_seo:Загрузка завершена. Обработано лидов: 44. Ошибок: 0
2022-02-28 11:22:33,213:domconnect.views:[Errno 2] No such file or directory: 'seo_archive/27-02-2022.json'
2022-02-28 11:53:35,033:django.utils.autoreload:C:\Dev\dj_domconnect\domconnect\lib_seo.py changed, reloading.
2022-02-28 11:53:48,856:domconnect.views:[Errno 2] No such file or directory: 'seo_archive/27-02-2022.json'
2022-02-28 11:54:09,570:domconnect.lib_seo:Обновение данных SEO запущено.
2022-02-28 11:54:10,108:domconnect.lib_seo:Загрузка завершена. Обработано сделок: 1. Ошибок: 0
2022-02-28 11:54:12,588:domconnect.lib_seo:Загрузка завершена. Обработано лидов: 95. Ошибок: 0
2022-02-28 11:54:12,734:domconnect.views:[Errno 2] No such file or directory: 'seo_archive/27-02-2022.json'
2022-02-28 12:00:03,007:domconnect.lib_seo:Расчет и сохранение данных SEO в кэш закончено.
2022-02-28 12:02:23,437:domconnect.views:[Errno 2] No such file or directory: 'seo_archive/27-02-2022.json'
2022-02-28 12:02:30,191:domconnect.lib_seo:Обновение данных SEO запущено.
2022-02-28 12:02:30,684:domconnect.lib_seo:Загрузка завершена. Обработано сделок: 1. Ошибок: 0
2022-02-28 12:02:32,964:domconnect.lib_seo:Загрузка завершена. Обработано лидов: 90. Ошибок: 0
2022-02-28 12:02:33,402:domconnect.views:[Errno 2] No such file or directory: 'seo_archive/27-02-2022.json'
2022-02-28 12:24:54,660:django.utils.autoreload:C:\Dev\dj_domconnect\domconnect\lib_seo.py changed, reloading.
2022-02-28 12:25:34,391:domconnect.views:[Errno 2] No such file or directory: 'seo_archive/27-02-2022.json'
2022-02-28 12:25:37,609:domconnect.lib_seo:Обновение данных SEO запущено.
2022-02-28 12:25:38,126:domconnect.lib_seo:Загрузка завершена. Обработано сделок: 1. Ошибок: 0
2022-02-28 12:25:40,582:domconnect.lib_seo:Загрузка завершена. Обработано лидов: 88. Ошибок: 0
2022-02-28 12:25:43,719:domconnect.views:[Errno 2] No such file or directory: 'seo_archive/27-02-2022.json'
2022-02-28 12:43:34,529:domconnect.lib_seo:Расчет и сохранение данных SEO в кэш закончено.
2022-02-28 13:00:02,229:django.utils.autoreload:C:\Dev\dj_domconnect\domconnect\views.py changed, reloading.
2022-02-28 13:00:23,900:django.utils.autoreload:C:\Dev\dj_domconnect\domconnect\views.py changed, reloading.
2022-02-28 13:01:00,821:django.utils.autoreload:C:\Dev\dj_domconnect\domconnect\views.py changed, reloading.
2022-02-28 13:01:15,521:django.utils.autoreload:C:\Dev\dj_domconnect\domconnect\views.py changed, reloading.
2022-02-28 13:03:25,722:django.utils.autoreload:C:\Dev\dj_domconnect\domconnect\lib_seo.py changed, reloading.
2022-02-28 13:03:36,120:django.utils.autoreload:C:\Dev\dj_domconnect\domconnect\views.py changed, reloading.
2022-02-28 13:04:00,981:domconnect.views:[Errno 2] No such file or directory: 'seo_archive/27-02-2022.json'
2022-02-28 13:04:04,487:domconnect.lib_seo:Обновение данных SEO запущено.
2022-02-28 13:04:05,092:domconnect.lib_seo:Загрузка завершена. Обработано сделок: 1. Ошибок: 0
2022-02-28 13:04:10,545:domconnect.lib_seo:Загрузка завершена. Обработано лидов: 157. Ошибок: 0
2022-02-28 13:25:33,444:domconnect.lib_seo:Расчет и сохранение данных SEO в кэш закончено.
2022-02-28 13:27:46,779:domconnect.lib_seo:Ошибка make_csv_text: try: list index out of range
2022-02-28 13:29:23,758:django.utils.autoreload:C:\Dev\dj_domconnect\domconnect\lib_seo.py changed, reloading.
2022-02-28 13:30:08,926:django.utils.autoreload:C:\Dev\dj_domconnect\domconnect\lib_seo.py changed, reloading.
2022-02-28 13:31:42,997:django.utils.autoreload:C:\Dev\dj_domconnect\domconnect\lib_seo.py changed, reloading.
2022-02-28 13:31:47,753:domconnect.lib_seo:Ошибка make_csv_text: try: list index out of range
2022-02-28 13:33:05,920:django.utils.autoreload:C:\Dev\dj_domconnect\domconnect\lib_seo.py changed, reloading.
2022-02-28 13:49:50,261:django.utils.autoreload:C:\Dev\dj_domconnect\domconnect\lib_seo.py changed, reloading.
2022-02-28 13:50:21,538:domconnect.lib_seo:Обновение данных SEO запущено.
2022-02-28 13:50:24,750:domconnect.views:[Errno 2] No such file or directory: 'seo_archive/27-02-2022.json'
2022-02-28 13:50:31,370:domconnect.lib_seo:Загрузка завершена. Обработано сделок: 1. Ошибок: 0
2022-02-28 13:50:36,690:domconnect.lib_seo:Загрузка завершена. Обработано лидов: 152. Ошибок: 0
2022-02-28 13:56:40,342:domconnect.lib_seo:Расчет и сохранение данных SEO в кэш закончено.
2022-03-03 09:49:59,173:django.utils.autoreload:C:\Dev\dj_domconnect\api\admin.py changed, reloading.
2022-03-03 09:50:13,913:django.request:Not Found: /favicon.ico
2022-03-03 10:00:39,703:django.utils.autoreload:C:\Dev\dj_domconnect\domconnect\views.py changed, reloading.
2022-03-03 10:01:45,610:django.utils.autoreload:C:\Dev\dj_domconnect\core\settings.py changed, reloading.
2022-03-03 10:07:01,565:django.utils.autoreload:C:\Dev\dj_domconnect\core\settings.py changed, reloading.
2022-03-03 10:08:55,919:django.request:Not Found: /favicon.ico
2022-03-03 10:12:11,381:django.utils.autoreload:C:\Dev\dj_domconnect\core\settings.py changed, reloading.
2022-03-03 10:13:54,359:django.utils.autoreload:C:\Dev\dj_domconnect\core\formats\ru\formats.py changed, reloading.
2022-03-03 10:20:08,438:django.utils.autoreload:C:\Dev\dj_domconnect\api\admin.py changed, reloading.
2022-03-03 10:25:01,100:django.utils.autoreload:C:\Dev\dj_domconnect\core\settings.py changed, reloading.
2022-03-03 10:56:55,974:domconnect.views:[Errno 2] No such file or directory: 'seo_archive/02-03-2022.json'
2022-03-03 10:57:41,873:django.utils.autoreload:C:\Dev\dj_domconnect\domconnect\views.py changed, reloading.
2022-03-03 10:57:46,009:domconnect.views:[Errno 2] No such file or directory: 'seo_archive/02-03-2022.json'
2022-03-03 11:03:30,898:django.utils.autoreload:C:\Dev\dj_domconnect\domconnect\views.py changed, reloading.
2022-03-03 11:03:39,460:domconnect.views:[WinError 2] Не удается найти указанный файл: '27-02-2022.json'
2022-03-03 11:04:06,378:django.utils.autoreload:C:\Dev\dj_domconnect\domconnect\views.py changed, reloading.
2022-03-03 11:04:14,376:domconnect.views:[WinError 2] Не удается найти указанный файл: '27-02-2022.json'
2022-03-03 11:05:04,451:django.utils.autoreload:C:\Dev\dj_domconnect\domconnect\views.py changed, reloading.
2022-03-03 11:05:45,368:domconnect.views:[WinError 2] Не удается найти указанный файл: '25-02-2022.json'
2022-03-03 11:07:45,076:domconnect.views:[WinError 2] Не удается найти указанный файл: '25-02-2022.json'
2022-03-03 11:08:08,893:django.utils.autoreload:C:\Dev\dj_domconnect\domconnect\views.py changed, reloading.
2022-03-03 11:08:15,247:domconnect.views:[WinError 2] Не удается найти указанный файл: '25-02-2022.json'
2022-03-03 11:09:13,433:django.utils.autoreload:C:\Dev\dj_domconnect\domconnect\views.py changed, reloading.
2022-03-03 11:09:17,326:domconnect.views:[WinError 2] Не удается найти указанный файл: '25-02-2022.json'
2022-03-03 11:10:27,580:django.utils.autoreload:C:\Dev\dj_domconnect\domconnect\views.py changed, reloading.
2022-03-03 11:10:52,534:django.utils.autoreload:C:\Dev\dj_domconnect\domconnect\views.py changed, reloading.
2022-03-03 11:11:06,948:django.utils.autoreload:C:\Dev\dj_domconnect\domconnect\views.py changed, reloading.
2022-03-03 11:11:11,921:domconnect.views:[WinError 2] Не удается найти указанный файл: '25-02-2022.json'
2022-03-03 11:12:55,698:django.utils.autoreload:C:\Dev\dj_domconnect\domconnect\views.py changed, reloading.
2022-03-03 11:15:50,939:django.utils.autoreload:C:\Dev\dj_domconnect\domconnect\views.py changed, reloading.
2022-03-03 11:15:55,796:domconnect.views:[WinError 3] Системе не удается найти указанный путь: 'seo_archive'
2022-03-03 11:18:12,347:django.utils.autoreload:C:\Dev\dj_domconnect\domconnect\views.py changed, reloading.
2022-03-03 11:18:17,064:domconnect.views:sort() takes no positional arguments
2022-03-03 11:19:22,423:django.utils.autoreload:C:\Dev\dj_domconnect\domconnect\views.py changed, reloading.
2022-03-03 11:19:27,501:domconnect.views:'WindowsPath' object has no attribute 'split'
2022-03-03 11:20:09,458:django.utils.autoreload:C:\Dev\dj_domconnect\domconnect\views.py changed, reloading.
2022-03-03 11:21:08,249:django.utils.autoreload:C:\Dev\dj_domconnect\domconnect\views.py changed, reloading.
2022-03-03 11:21:30,908:domconnect.views:'resverse' is an invalid keyword argument for sort()
2022-03-03 11:24:19,251:django.utils.autoreload:C:\Dev\dj_domconnect\domconnect\views.py changed, reloading.
2022-03-03 11:31:18,003:django.utils.autoreload:C:\Dev\dj_domconnect\domconnect\views.py changed, reloading.
2022-03-03 11:31:24,303:domconnect.views:[Errno 2] No such file or directory: '29-02-2022.json'
2022-03-03 11:32:22,578:django.utils.autoreload:C:\Dev\dj_domconnect\domconnect\views.py changed, reloading.
2022-03-03 11:34:52,780:django.utils.autoreload:C:\Dev\dj_domconnect\domconnect\views.py changed, reloading.
2022-03-03 11:36:48,424:django.utils.autoreload:C:\Dev\dj_domconnect\domconnect\lib_seo.py changed, reloading.
2022-03-03 11:37:41,447:domconnect.lib_seo:Обновение данных SEO запущено.
2022-03-03 11:38:16,576:domconnect.lib_seo:Загрузка завершена. Обработано сделок: 839. Ошибок: 0
2022-03-03 11:40:50,385:domconnect.lib_seo:Загрузка завершена. Обработано лидов: 3901. Ошибок: 0
2022-03-03 11:48:57,463:domconnect.lib_seo:Расчет и сохранение данных SEO в кэш закончено.
2022-03-03 11:53:22,680:django.utils.autoreload:C:\Dev\dj_domconnect\domconnect\views.py changed, reloading.
2022-03-03 12:08:53,014:django.utils.autoreload:C:\Dev\dj_domconnect\domconnect\views.py changed, reloading.
2022-03-03 12:09:45,923:django.utils.autoreload:C:\Dev\dj_domconnect\domconnect\views.py changed, reloading.
2022-03-03 12:13:47,133:django.utils.autoreload:C:\Dev\dj_domconnect\domconnect\views.py changed, reloading.
2022-03-03 12:46:08,409:django.utils.autoreload:C:\Dev\dj_domconnect\domconnect\views.py changed, reloading.
2022-03-03 14:24:20,187:django.utils.autoreload:C:\Dev\dj_domconnect\domconnect\lib_seo.py changed, reloading.
2022-03-03 14:25:04,038:django.utils.autoreload:C:\Dev\dj_domconnect\domconnect\views.py changed, reloading.
2022-03-08 15:42:25,291:django.request:Not Found: /favicon.ico
2022-03-08 15:53:03,564:django.request:Internal Server Error: /api/get_bots_vizit
Traceback (most recent call last):
  File "c:\Dev\dj_domconnect\venv\lib\site-packages\django\core\handlers\exception.py", line 34, in inner
    response = get_response(request)
  File "c:\Dev\dj_domconnect\venv\lib\site-packages\django\core\handlers\base.py", line 115, in _get_response
    response = self.process_exception_by_middleware(e, request)
  File "c:\Dev\dj_domconnect\venv\lib\site-packages\django\core\handlers\base.py", line 113, in _get_response
    response = wrapped_callback(request, *callback_args, **callback_kwargs)
  File "c:\Dev\dj_domconnect\api\views.py", line 203, in get_bots_vizit
    data = json.dumps(lst_bots_vizit)
  File "C:\Users\al-si\AppData\Local\Programs\Python\Python39\lib\json\__init__.py", line 231, in dumps
    return _default_encoder.encode(obj)
  File "C:\Users\al-si\AppData\Local\Programs\Python\Python39\lib\json\encoder.py", line 199, in encode
    chunks = self.iterencode(o, _one_shot=True)
  File "C:\Users\al-si\AppData\Local\Programs\Python\Python39\lib\json\encoder.py", line 257, in iterencode
    return _iterencode(o, 0)
  File "C:\Users\al-si\AppData\Local\Programs\Python\Python39\lib\json\encoder.py", line 179, in default
    raise TypeError(f'Object of type {o.__class__.__name__} '
TypeError: Object of type BotVisit is not JSON serializable
2022-03-08 15:54:03,836:django.request:Internal Server Error: /api/get_bots_vizit
Traceback (most recent call last):
  File "c:\Dev\dj_domconnect\venv\lib\site-packages\django\core\handlers\exception.py", line 34, in inner
    response = get_response(request)
  File "c:\Dev\dj_domconnect\venv\lib\site-packages\django\core\handlers\base.py", line 115, in _get_response
    response = self.process_exception_by_middleware(e, request)
  File "c:\Dev\dj_domconnect\venv\lib\site-packages\django\core\handlers\base.py", line 113, in _get_response
    response = wrapped_callback(request, *callback_args, **callback_kwargs)
  File "c:\Dev\dj_domconnect\api\views.py", line 203, in get_bots_vizit
    data = json.dumps(lst_bots_vizit)
  File "C:\Users\al-si\AppData\Local\Programs\Python\Python39\lib\json\__init__.py", line 231, in dumps
    return _default_encoder.encode(obj)
  File "C:\Users\al-si\AppData\Local\Programs\Python\Python39\lib\json\encoder.py", line 199, in encode
    chunks = self.iterencode(o, _one_shot=True)
  File "C:\Users\al-si\AppData\Local\Programs\Python\Python39\lib\json\encoder.py", line 257, in iterencode
    return _iterencode(o, 0)
  File "C:\Users\al-si\AppData\Local\Programs\Python\Python39\lib\json\encoder.py", line 179, in default
    raise TypeError(f'Object of type {o.__class__.__name__} '
TypeError: Object of type BotVisit is not JSON serializable
2022-03-08 15:55:24,694:django.utils.autoreload:C:\Dev\dj_domconnect\api\views.py changed, reloading.
2022-03-08 15:55:32,898:django.request:Internal Server Error: /api/get_bots_vizit
Traceback (most recent call last):
  File "c:\Dev\dj_domconnect\venv\lib\site-packages\django\core\handlers\exception.py", line 34, in inner
    response = get_response(request)
  File "c:\Dev\dj_domconnect\venv\lib\site-packages\django\core\handlers\base.py", line 115, in _get_response
    response = self.process_exception_by_middleware(e, request)
  File "c:\Dev\dj_domconnect\venv\lib\site-packages\django\core\handlers\base.py", line 113, in _get_response
    response = wrapped_callback(request, *callback_args, **callback_kwargs)
  File "c:\Dev\dj_domconnect\api\views.py", line 204, in get_bots_vizit
    data = json.dumps(lst_bots_vizit)
  File "C:\Users\al-si\AppData\Local\Programs\Python\Python39\lib\json\__init__.py", line 231, in dumps
    return _default_encoder.encode(obj)
  File "C:\Users\al-si\AppData\Local\Programs\Python\Python39\lib\json\encoder.py", line 199, in encode
    chunks = self.iterencode(o, _one_shot=True)
  File "C:\Users\al-si\AppData\Local\Programs\Python\Python39\lib\json\encoder.py", line 257, in iterencode
    return _iterencode(o, 0)
  File "C:\Users\al-si\AppData\Local\Programs\Python\Python39\lib\json\encoder.py", line 179, in default
    raise TypeError(f'Object of type {o.__class__.__name__} '
TypeError: Object of type BotVisit is not JSON serializable
2022-03-08 15:57:25,587:django.utils.autoreload:C:\Dev\dj_domconnect\api\views.py changed, reloading.
2022-03-08 15:57:30,952:django.utils.autoreload:C:\Dev\dj_domconnect\api\views.py changed, reloading.
2022-03-08 15:57:35,476:django.request:Internal Server Error: /api/get_bots_vizit
Traceback (most recent call last):
  File "c:\Dev\dj_domconnect\venv\lib\site-packages\django\core\handlers\exception.py", line 34, in inner
    response = get_response(request)
  File "c:\Dev\dj_domconnect\venv\lib\site-packages\django\core\handlers\base.py", line 115, in _get_response
    response = self.process_exception_by_middleware(e, request)
  File "c:\Dev\dj_domconnect\venv\lib\site-packages\django\core\handlers\base.py", line 113, in _get_response
    response = wrapped_callback(request, *callback_args, **callback_kwargs)
  File "c:\Dev\dj_domconnect\api\views.py", line 202, in get_bots_vizit
    lst_bots_vizit = [k for k in obj_bots_vizit.keys()]
AttributeError: 'QuerySet' object has no attribute 'keys'
2022-03-08 15:59:31,865:django.utils.autoreload:C:\Dev\dj_domconnect\api\views.py changed, reloading.
2022-03-08 15:59:36,208:django.request:Internal Server Error: /api/get_bots_vizit
Traceback (most recent call last):
  File "c:\Dev\dj_domconnect\venv\lib\site-packages\django\core\handlers\exception.py", line 34, in inner
    response = get_response(request)
  File "c:\Dev\dj_domconnect\venv\lib\site-packages\django\core\handlers\base.py", line 115, in _get_response
    response = self.process_exception_by_middleware(e, request)
  File "c:\Dev\dj_domconnect\venv\lib\site-packages\django\core\handlers\base.py", line 113, in _get_response
    response = wrapped_callback(request, *callback_args, **callback_kwargs)
  File "c:\Dev\dj_domconnect\api\views.py", line 208, in get_bots_vizit
    data = json.dumps(lst_bots_vizit)
  File "C:\Users\al-si\AppData\Local\Programs\Python\Python39\lib\json\__init__.py", line 231, in dumps
    return _default_encoder.encode(obj)
  File "C:\Users\al-si\AppData\Local\Programs\Python\Python39\lib\json\encoder.py", line 199, in encode
    chunks = self.iterencode(o, _one_shot=True)
  File "C:\Users\al-si\AppData\Local\Programs\Python\Python39\lib\json\encoder.py", line 257, in iterencode
    return _iterencode(o, 0)
  File "C:\Users\al-si\AppData\Local\Programs\Python\Python39\lib\json\encoder.py", line 179, in default
    raise TypeError(f'Object of type {o.__class__.__name__} '
TypeError: Object of type datetime is not JSON serializable
2022-03-08 16:06:55,715:django.utils.autoreload:C:\Dev\dj_domconnect\api\views.py changed, reloading.
2022-03-08 16:07:00,338:django.request:Internal Server Error: /api/get_bots_vizit
Traceback (most recent call last):
  File "c:\Dev\dj_domconnect\venv\lib\site-packages\django\core\handlers\exception.py", line 34, in inner
    response = get_response(request)
  File "c:\Dev\dj_domconnect\venv\lib\site-packages\django\core\handlers\base.py", line 115, in _get_response
    response = self.process_exception_by_middleware(e, request)
  File "c:\Dev\dj_domconnect\venv\lib\site-packages\django\core\handlers\base.py", line 113, in _get_response
    response = wrapped_callback(request, *callback_args, **callback_kwargs)
  File "c:\Dev\dj_domconnect\api\views.py", line 211, in get_bots_vizit
    data = json.dumps(lst_bots_vizit)
  File "C:\Users\al-si\AppData\Local\Programs\Python\Python39\lib\json\__init__.py", line 231, in dumps
    return _default_encoder.encode(obj)
  File "C:\Users\al-si\AppData\Local\Programs\Python\Python39\lib\json\encoder.py", line 199, in encode
    chunks = self.iterencode(o, _one_shot=True)
  File "C:\Users\al-si\AppData\Local\Programs\Python\Python39\lib\json\encoder.py", line 257, in iterencode
    return _iterencode(o, 0)
  File "C:\Users\al-si\AppData\Local\Programs\Python\Python39\lib\json\encoder.py", line 179, in default
    raise TypeError(f'Object of type {o.__class__.__name__} '
TypeError: Object of type datetime is not JSON serializable
2022-03-08 16:07:33,942:django.utils.autoreload:C:\Dev\dj_domconnect\api\models.py changed, reloading.
2022-03-08 16:07:39,189:django.request:Internal Server Error: /api/get_bots_vizit
Traceback (most recent call last):
  File "c:\Dev\dj_domconnect\venv\lib\site-packages\django\core\handlers\exception.py", line 34, in inner
    response = get_response(request)
  File "c:\Dev\dj_domconnect\venv\lib\site-packages\django\core\handlers\base.py", line 115, in _get_response
    response = self.process_exception_by_middleware(e, request)
  File "c:\Dev\dj_domconnect\venv\lib\site-packages\django\core\handlers\base.py", line 113, in _get_response
    response = wrapped_callback(request, *callback_args, **callback_kwargs)
  File "c:\Dev\dj_domconnect\api\views.py", line 211, in get_bots_vizit
    data = json.dumps(lst_bots_vizit)
  File "C:\Users\al-si\AppData\Local\Programs\Python\Python39\lib\json\__init__.py", line 231, in dumps
    return _default_encoder.encode(obj)
  File "C:\Users\al-si\AppData\Local\Programs\Python\Python39\lib\json\encoder.py", line 199, in encode
    chunks = self.iterencode(o, _one_shot=True)
  File "C:\Users\al-si\AppData\Local\Programs\Python\Python39\lib\json\encoder.py", line 257, in iterencode
    return _iterencode(o, 0)
  File "C:\Users\al-si\AppData\Local\Programs\Python\Python39\lib\json\encoder.py", line 179, in default
    raise TypeError(f'Object of type {o.__class__.__name__} '
TypeError: Object of type datetime is not JSON serializable
2022-03-08 16:07:49,573:django.utils.autoreload:C:\Dev\dj_domconnect\api\models.py changed, reloading.
2022-03-08 16:07:54,730:django.request:Internal Server Error: /api/get_bots_vizit
Traceback (most recent call last):
  File "c:\Dev\dj_domconnect\venv\lib\site-packages\django\core\handlers\exception.py", line 34, in inner
    response = get_response(request)
  File "c:\Dev\dj_domconnect\venv\lib\site-packages\django\core\handlers\base.py", line 115, in _get_response
    response = self.process_exception_by_middleware(e, request)
  File "c:\Dev\dj_domconnect\venv\lib\site-packages\django\core\handlers\base.py", line 113, in _get_response
    response = wrapped_callback(request, *callback_args, **callback_kwargs)
  File "c:\Dev\dj_domconnect\api\views.py", line 211, in get_bots_vizit
    data = json.dumps(lst_bots_vizit)
  File "C:\Users\al-si\AppData\Local\Programs\Python\Python39\lib\json\__init__.py", line 231, in dumps
    return _default_encoder.encode(obj)
  File "C:\Users\al-si\AppData\Local\Programs\Python\Python39\lib\json\encoder.py", line 199, in encode
    chunks = self.iterencode(o, _one_shot=True)
  File "C:\Users\al-si\AppData\Local\Programs\Python\Python39\lib\json\encoder.py", line 257, in iterencode
    return _iterencode(o, 0)
  File "C:\Users\al-si\AppData\Local\Programs\Python\Python39\lib\json\encoder.py", line 179, in default
    raise TypeError(f'Object of type {o.__class__.__name__} '
TypeError: Object of type datetime is not JSON serializable
2022-03-08 16:17:50,726:django.utils.autoreload:C:\Dev\dj_domconnect\api\views.py changed, reloading.
2022-03-08 16:18:04,269:django.request:Internal Server Error: /api/get_bots_vizit
Traceback (most recent call last):
  File "c:\Dev\dj_domconnect\venv\lib\site-packages\django\core\handlers\exception.py", line 34, in inner
    response = get_response(request)
  File "c:\Dev\dj_domconnect\venv\lib\site-packages\django\core\handlers\base.py", line 115, in _get_response
    response = self.process_exception_by_middleware(e, request)
  File "c:\Dev\dj_domconnect\venv\lib\site-packages\django\core\handlers\base.py", line 113, in _get_response
    response = wrapped_callback(request, *callback_args, **callback_kwargs)
  File "c:\Dev\dj_domconnect\api\views.py", line 214, in get_bots_vizit
    data = json.dumps(lst_bots_vizit, default=json_datetime, indent=1)
  File "C:\Users\al-si\AppData\Local\Programs\Python\Python39\lib\json\__init__.py", line 234, in dumps
    return cls(
  File "C:\Users\al-si\AppData\Local\Programs\Python\Python39\lib\json\encoder.py", line 201, in encode
    chunks = list(chunks)
  File "C:\Users\al-si\AppData\Local\Programs\Python\Python39\lib\json\encoder.py", line 429, in _iterencode
    yield from _iterencode_list(o, _current_indent_level)
  File "C:\Users\al-si\AppData\Local\Programs\Python\Python39\lib\json\encoder.py", line 325, in _iterencode_list
    yield from chunks
  File "C:\Users\al-si\AppData\Local\Programs\Python\Python39\lib\json\encoder.py", line 405, in _iterencode_dict
    yield from chunks
  File "C:\Users\al-si\AppData\Local\Programs\Python\Python39\lib\json\encoder.py", line 438, in _iterencode
    o = _default(o)
  File "c:\Dev\dj_domconnect\api\views.py", line 197, in json_datetime
    if isinstance(o, (datetime.date, datetime.datetime)):
AttributeError: type object 'datetime.datetime' has no attribute 'datetime'
2022-03-08 16:19:59,889:django.utils.autoreload:C:\Dev\dj_domconnect\api\views.py changed, reloading.
2022-03-08 16:20:04,571:django.request:Internal Server Error: /api/get_bots_vizit
Traceback (most recent call last):
  File "c:\Dev\dj_domconnect\venv\lib\site-packages\django\core\handlers\exception.py", line 34, in inner
    response = get_response(request)
  File "c:\Dev\dj_domconnect\venv\lib\site-packages\django\core\handlers\base.py", line 115, in _get_response
    response = self.process_exception_by_middleware(e, request)
  File "c:\Dev\dj_domconnect\venv\lib\site-packages\django\core\handlers\base.py", line 113, in _get_response
    response = wrapped_callback(request, *callback_args, **callback_kwargs)
  File "c:\Dev\dj_domconnect\api\views.py", line 214, in get_bots_vizit
    data = json.dumps(lst_bots_vizit, default=json_datetime, indent=1)
  File "C:\Users\al-si\AppData\Local\Programs\Python\Python39\lib\json\__init__.py", line 234, in dumps
    return cls(
  File "C:\Users\al-si\AppData\Local\Programs\Python\Python39\lib\json\encoder.py", line 201, in encode
    chunks = list(chunks)
  File "C:\Users\al-si\AppData\Local\Programs\Python\Python39\lib\json\encoder.py", line 429, in _iterencode
    yield from _iterencode_list(o, _current_indent_level)
  File "C:\Users\al-si\AppData\Local\Programs\Python\Python39\lib\json\encoder.py", line 325, in _iterencode_list
    yield from chunks
  File "C:\Users\al-si\AppData\Local\Programs\Python\Python39\lib\json\encoder.py", line 405, in _iterencode_dict
    yield from chunks
  File "C:\Users\al-si\AppData\Local\Programs\Python\Python39\lib\json\encoder.py", line 438, in _iterencode
    o = _default(o)
  File "c:\Dev\dj_domconnect\api\views.py", line 197, in json_datetime
    if isinstance(o, (datetime.date, datetime)):
TypeError: isinstance() arg 2 must be a type or tuple of types
2022-03-08 16:20:24,072:django.utils.autoreload:C:\Dev\dj_domconnect\api\views.py changed, reloading.
2022-03-08 16:20:28,140:django.request:Internal Server Error: /api/get_bots_vizit
Traceback (most recent call last):
  File "c:\Dev\dj_domconnect\venv\lib\site-packages\django\core\handlers\exception.py", line 34, in inner
    response = get_response(request)
  File "c:\Dev\dj_domconnect\venv\lib\site-packages\django\core\handlers\base.py", line 115, in _get_response
    response = self.process_exception_by_middleware(e, request)
  File "c:\Dev\dj_domconnect\venv\lib\site-packages\django\core\handlers\base.py", line 113, in _get_response
    response = wrapped_callback(request, *callback_args, **callback_kwargs)
  File "c:\Dev\dj_domconnect\api\views.py", line 214, in get_bots_vizit
    data = json.dumps(lst_bots_vizit, default=json_datetime, indent=1)
  File "C:\Users\al-si\AppData\Local\Programs\Python\Python39\lib\json\__init__.py", line 234, in dumps
    return cls(
  File "C:\Users\al-si\AppData\Local\Programs\Python\Python39\lib\json\encoder.py", line 201, in encode
    chunks = list(chunks)
  File "C:\Users\al-si\AppData\Local\Programs\Python\Python39\lib\json\encoder.py", line 429, in _iterencode
    yield from _iterencode_list(o, _current_indent_level)
  File "C:\Users\al-si\AppData\Local\Programs\Python\Python39\lib\json\encoder.py", line 325, in _iterencode_list
    yield from chunks
  File "C:\Users\al-si\AppData\Local\Programs\Python\Python39\lib\json\encoder.py", line 405, in _iterencode_dict
    yield from chunks
  File "C:\Users\al-si\AppData\Local\Programs\Python\Python39\lib\json\encoder.py", line 438, in _iterencode
    o = _default(o)
  File "c:\Dev\dj_domconnect\api\views.py", line 197, in json_datetime
    if isinstance(o, (datetime.date, datetime, )):
TypeError: isinstance() arg 2 must be a type or tuple of types
2022-03-08 16:20:47,037:django.utils.autoreload:C:\Dev\dj_domconnect\api\views.py changed, reloading.
2022-03-08 16:22:07,566:django.utils.autoreload:C:\Dev\dj_domconnect\api\views.py changed, reloading.
2022-03-08 16:26:22,866:django.utils.autoreload:C:\Dev\dj_domconnect\api\views.py changed, reloading.
2022-03-08 16:26:58,748:django.utils.autoreload:C:\Dev\dj_domconnect\api\views.py changed, reloading.
2022-03-10 08:33:04,402:django.request:Not Found: /favicon.ico
2022-03-10 08:33:44,367:django.utils.autoreload:C:\Dev\dj_domconnect\api\admin.py changed, reloading.
2022-03-21 09:46:23,416:django.request:Not Found: /favicon.ico
